Workbook

Sheet Patient Prices
K2: Price | P2: Price | R2: Friends & Family: BAC is an additional price
A3: New Patient | I3: ='BPC+TB500'!A1 -> BPC157 + TB500 20mg | N3: MOTS-C 10mg | U3: BOTTLES
B4: Without Boodwork | C4: $200 covers the first two visits | J4: Month 1 | K4: ='BPC+TB500'!K37 -> 298 | O4: Month 1 | P4: ='MotsC 10'!K36 -> 138 | R4: ='Pep Costs'!A5 -> AOD-9604 5mg | S4: ='Pep Costs'!C5 -> 55 | V4: ='Pep Costs'!A45 -> Selank 10mg | W4: ='Pep Costs'!C45 -> 145
D5: 1st visit: Health HX and RX for Blood | J5: Month 2 | K5: ='BPC+TB500'!K50 -> 376 | O5: Month 2 | P5: ='MotsC 10'!K48 -> 321 | R5: ='Pep Costs'!A6 -> BAC Water 10ml | S5: 5 | V5: ='Pep Costs'!A46 -> Semax 10mg | W5: ='Pep Costs'!C46 -> 145
D6: 2nd visit: review Blood and RX for Peptides | J6: Month 3 | K6: ='BPC+TB500'!K62 -> 376 | O6: Month 3++ | P6: ='MotsC 10'!K60 -> 458 | R6: ='Pep Costs'!A7 -> BB10 5/5 | S6: ='Pep Costs'!C7 -> 165 | V6: ='Pep Costs'!A47 -> SS-31 10mg | W6: ='Pep Costs'!C47 -> 207.75
J7: Mont 4+ per RX | N7: ='NAD+ Acute'!A1 -> NAD+ 1000mg (Acute) | R7: ='Pep Costs'!A8 -> BB20 | S7: ='Pep Costs'!C8 -> 185 | V7: ='Pep Costs'!A48 -> Sterile Deion Water 10ml | W7: ='Pep Costs'!C48 -> 115
B8: WITH Bloodwork | C8: 150 | I8: ='Wolv Slow Tit'!A1 -> BPC157 + TB500 20mg (Slow Titration) | O8: Month 1 | P8: ='NAD+ Acute'!K36 -> 523 | R8: ='Pep Costs'!A10 -> BPC-157 10mg | S8: ='Pep Costs'!C10 -> 148.4875 | V8: ='Pep Costs'!A50 -> TB500 10mg | W8: ='Pep Costs'!C50 -> 160
C9: (1) visit: review blood and RX for Peptides | J9: Month 1 | K9: ='Wolv Slow Tit'!K18 -> 122 | O9: Month 2 | P9: ='NAD+ Acute'!K48 -> 542 | R9: ='Pep Costs'!A11 -> BPC-157 /TB500 20 mg | S9: ='Pep Costs'!C11 -> 250 | V9: ='Pep Costs'!A51 -> Tesamorelin 10mg | W9: ='Pep Costs'!C51 -> 175
J10: Month 2 | K10: ='Wolv Slow Tit'!K30 -> 215 | O10: Month 3 | P10: ='NAD+ Acute'!K60 -> 542 | R10: ='Pep Costs'!A12 -> BPC-157 20 mg | S10: ='Pep Costs'!C12 -> 255 | V10: ='Pep Costs'!A52 -> Tesofensine | W10: ='Pep Costs'!C52 -> 225
A11: Follow-up Appointments | J11: Month 3 | K11: ='Wolv Slow Tit'!K42 -> 215 | O11: Mont 4+ per RX | R11: ='Pep Costs'!A13 -> Cag 5mg | S11: ='Pep Costs'!C13 -> 165 | V11: ='Pep Costs'!A53 -> Tirz 10mg | W11: ='Pep Costs'!C53 -> 205
B12: 20 minutes | C12: Face to Face $100 | J12: Mont 4+ per RX * | N12: ='NAD semiAct'!A1 -> NAD+ 1000mg (Semi-Acute) | R12: ='Pep Costs'!A14 -> Cag 10mg | S12: ='Pep Costs'!C14 -> 205 | V12: ='Pep Costs'!A54 -> Tirz 15mg | W12: ='Pep Costs'!C54 -> 245
C13: Telehealth $75 | I13: ='Wolv Maintenance'!A1 -> BPC157 + TB500 20mg (Maintenance) | O13: Month 1 | P13: ='NAD semiAct'!K19 -> 252 | R13: ='Pep Costs'!A15 -> CJC-1295/Ipa 5/5 | S13: ='Pep Costs'!C15 -> 160 | V13: ='Pep Costs'!A55 -> Tirz 30mg | W13: ='Pep Costs'!C55 -> 295
J14: Maintenance | K14: ='Wolv Maintenance'!K18 -> 150 | L14: 3 month min. | O14: Month 2 | P14: ='NAD semiAct'!K31 -> 310 | R14: ='Pep Costs'!A16 -> DSIP 5mg | S14: ='Pep Costs'!C16 -> 137 | V14: ='Pep Costs'!A56 -> Tirz 5mg | W14: ='Pep Costs'!C56 -> 175
I15: ='DSIP 5mg'!A1 -> DSIP 5mg | O15: Month 3 | P15: ='NAD semiAct'!K43 -> 310 | R15: ='Pep Costs'!A17 -> DSIP 10mg | S15: ='Pep Costs'!C17 -> 147 | V15: ='Pep Costs'!A57 -> Tirz 60mg | W15: ='Pep Costs'!C57 -> 355
A16: Multiple Peptides: | J16: Month 1 | K16: ='DSIP 5mg'!K35 -> 153 | O16: Mont 4+ per RX | R16: ='Pep Costs'!A18 -> Epithalon 5mg | S16: ='Pep Costs'!C18 -> 137 | V16: ='Pep Costs'!A58 -> VIP 10mg | W16: ='Pep Costs'!C58 -> 155
B17: Patient can ONLY start ONE at a time to watch for allergic reactions, otherwise it is impossible to know which one the patient is allergic to. So one this week and one next week So start #1 on the first week and then next week they can come start the next pept | J17: Month 2 | K17: ='DSIP 5mg'!K47 -> 251 | N17: ='PT-141 10mg'!A1 -> PT-141 10mg | R17: ='Pep Costs'!A19 -> Epithalon 10mg | S17: ='Pep Costs'!C19 -> 145 | V17: ='Pep Costs'!A59 -> Tablets/Caps
J18: Month 3 | K18: ='DSIP 5mg'!K65 -> 285 | O18: Week 1-8 | P18: 15 Unit | R18: ='Pep Costs'!A20 -> Epithalon 50mg | S18: ='Pep Costs'!C20 -> 175.425 | V18: ='Pep Costs'!A60 -> 5 Amino 1q 50mg | W18: ='Pep Costs'!C60 -> 170.0375
J19: Mont 4+ per RX | O19: Week 9-12 | P19: 30 Unit | R19: ='Pep Costs'!A21 -> GHK-CU 50mg | S19: ='Pep Costs'!C21 -> 145 | V19: ='Pep Costs'!A61 -> BPC 500mcg | W19: ='Pep Costs'!C61 -> 214
A20: If they decide to randomly start a new peptide, they will need to come in monthly (at least) for that pept. | I20: ='DSIP 10mg'!A1 -> DSIP 10mg | O20: Week 13-16 | P20: 45 Unit | R20: ='Pep Costs'!A22 -> GHK-CU 100mg | S20: ='Pep Costs'!C22 -> 165 | V20: ='Pep Costs'!A62 -> Methaline Blue 20mg | W20: ='Pep Costs'!C62 -> 185
J21: Month 1 | K21: ='DSIP 10mg'!K34 -> 85 | N21: ='Tesam 10'!A1 -> Tesamorelin 10mg | R21: ='Pep Costs'!A23 -> GLOW 50mg | S21: ='Pep Costs'!C23 -> 165 | V21: ='Pep Costs'!A63 -> Tesofensine 500mcg (1tab daily) | W21: ='Pep Costs'!C63 -> 165
J22: Month 2 | K22: ='DSIP 10mg'!K46 -> 139 | O22: Month 1 | P22: ='Tesam 10'!K33 -> 560 | R22: ='Pep Costs'!A24 -> GLOW 70mg | S22: ='Pep Costs'!C24 -> 205 | V22: ='Pep Costs'!A64 -> Semaglutide 10mg | W22: ='Pep Costs'!C64 -> 185
J23: Month 3 | K23: ='DSIP 10mg'!K46 -> 139 | O23: Month 2 | P23: ='Tesam 10'!K45 -> 747 | R23: ='Pep Costs'!A25 -> Glutathione 600mg | S23: ='Pep Costs'!C25 -> 145 | V23: ='Pep Costs'!A65 -> GHK-CU 100mg | W23: ='Pep Costs'!C65 -> 165
H24: **so they are always "seen" at the beginnng of that month's TX | J24: Mont 4+ per RX | O24: Month 3 | P24: ='Tesam 10'!K45 -> 747 | R24: ='Pep Costs'!A26 -> HCG 5000IU | S24: ='Pep Costs'!C26 -> 145 | V24: ='Pep Costs'!A66 -> BPC-157 10mg | W24: ='Pep Costs'!C66 -> 155
A25: • Month 1 (Week 1-4): RX visit | I25: ='GHK-CU 50'!A1 -> GHK-CU 50mg | O25: Mont 4+ per RX | R25: ='Pep Costs'!A27 -> Hexarelin 10 mg | S25: ='Pep Costs'!C27 -> 170 | V25: ='Pep Costs'!A67 -> SLU PP 332(500mcg)x100 | W25: ='Pep Costs'!C67 -> 170
J26: Month 1 | K26: ='GHK-CU 50'!K34 -> 92 | N26: GLP-3Re 20mg | R26: ='Pep Costs'!A28 -> HGH 15IU | S26: ='Pep Costs'!C28 -> 165 | V26: ='Pep Costs'!A68 -> SLUP PP 332(1mg) x100 | W26: ='Pep Costs'!C68 -> 190
A27: • Month 2 (start of Week 5-8): vitals, monitor, take home RX for month 2 | J27: Month 2 | K27: ='GHK-CU 50'!K46 -> 138 | O27: $350/month | R27: ='Pep Costs'!A29 -> HGH 24IU | S27: ='Pep Costs'!C29 -> 177 | V27: ='Pep Costs'!A69 -> Slu PP 332(5mg)x100 | W27: ='Pep Costs'!C69 -> 210
J28: Month 3 | K28: ='GHK-CU 50'!K58 -> 183 | R28: ='Pep Costs'!A30 -> HGH 36IU | S28: ='Pep Costs'!C30 -> 190 | V28: ='Pep Costs'!A70 -> Nasal Sprays
A29: • Month 3 (start of Week 9-12): vitals, monitor, take home RX for month 3, AND RX BLOOD | J29: Mont 4+ per RX | N29: ='Tirz 30mg'!A1 -> Tirzepatide 30mg | R29: ='Pep Costs'!A31 -> Kisspep 10mg | S29: ='Pep Costs'!C31 -> 150 | V29: ='Pep Costs'!A71 -> DSIP | W29: ='Pep Costs'!C71 -> 170
I30: ='Glow 70'!A1 -> GLOW 70 | J30: Month 1 | K30: ='Glow 70'!K36 -> 209 | O30: $350/month | R30: ='Pep Costs'!A32 -> KLOW 80mg | S30: ='Pep Costs'!C32 -> 225 | V30: ='Pep Costs'!A72 -> Selank Nasal | W30: ='Pep Costs'!C72 -> 175
A31: • Month 4&5 (start of Week 13-20): vitals, monitor, review BLOOD (no blood no more RX), at NP discretion pt can return in 4 or 8 weeks (send home RX accordingly). | J31: By RX only | R31: ='Pep Costs'!A33 -> Lipo-C w/ B12 | S31: ='Pep Costs'!C33 -> 155 | V31: ='Pep Costs'!A73 -> Semax Nasal | W31: ='Pep Costs'!C73 -> 175
I32: =Kissp!A1 -> Kisspeptine 10mg | R32: ='Pep Costs'!A34 -> Melatonin-11 | S32: ='Pep Costs'!C34 -> 145 | V32: ='Pep Costs'!A74 -> Oxytocin Nasal | W32: ='Pep Costs'!C74 -> 86.25
J33: Month 1 | K33: =Kissp!K33 -> 71 | R33: ='Pep Costs'!A35 -> Mots-C 10mg | S33: ='Pep Costs'!C35 -> 159.2625
A34: • Month 6&7 (start of Week 21-28): vitals, monitor, at NP discretion pt can return in 4 or 8 weeks (send home RX accordingly). RX for blood and review over Telehealth | J34: Month 2 | K34: =Kissp!K45 -> 95 | R34: ='Pep Costs'!A36 -> MT 2 10mg | S34: ='Pep Costs'!C36 -> 145
J35: Month 3 | K35: =Kissp!K57 -> 95 | R35: ='Pep Costs'!A37 -> NAD+ 1000mg | S35: ='Pep Costs'!C37 -> 175
J36: Mont 4+ per RX | R36: ='Pep Costs'!A38 -> NAD+ 500mg | S36: ='Pep Costs'!C38 -> 155
A37: • Month 8,9&10 (start of Week 29-36): *if they did not do blood then no more RX…..Vitals, monitor, at NP discretion pt can return in 4-12 weeks (send home RX accordingly). | I37: ='KLOW 80'!A1 -> KLOW 80mg | R37: ='Pep Costs'!A40 -> Oxytocin 5mg | S37: ='Pep Costs'!C40 -> 145 | V37: Peptide Pen | W37: 60
J38: Month 1 | K38: ='KLOW 80'!K33 -> 250 | R38: ='Pep Costs'!A41 -> PT141 10 mg | S38: ='Pep Costs'!C41 -> 155 | V38: Pack of 15 needles, 15 alcohol Prep | W38: 10
J39: Month 2 | K39: ='KLOW 80'!K45 -> 500 | O39: Peptide Pen | Q39: 85 | R39: ='Pep Costs'!A42 -> Reta 10mg | S39: ='Pep Costs'!C42 -> 200 | V39: Pack of 30 needles, 15 alcohol Prep | W39: 15
A40: • Month 11,12&13 (start of Week 37-48): vitals, monitor, at NP discretion pt can return in 4-12 weeks (send home RX accordingly). RX for blood and review over Telehealth | J40: Month 3 | K40: ='KLOW 80'!K57 -> 341 | O40: Pack of 15 needles & alcohol Prep | Q40: 10 | R40: ='Pep Costs'!A43 -> Reta 20mg | S40: 350 | V40: Pep Pen Cartridge | W40: 1
J41: Mont 4+ per RX | O41: Pack of 30 needles & 15 alcohol Prep | Q41: 15 | R41: ='Pep Costs'!A44 -> Reta 30mg | S41: ='Pep Costs'!C44 -> 270
...

Sheet Pep Costs
A1: VIP Membership | B1: N/A | D1: 0 | E1: 200
A2: Monthly Offive Visit | D2: $150/visit | E2: $0/visit
A4: Peptide | B4: 2/2/2026 COST | C4: Plus $100 (includes BAC) | D4: Regular Price Per Unit | E4: VIP Price Per Unit | F4: Column1 | K4: Week 1-4 | L4: Week 5-8 | M4: Week 9-12 | N4: Week 13-16
A5: AOD-9604 5mg | B5: 45 | C5: =+B5+10 -> 55 | F5: downloaded
A6: BAC Water 10ml | B6: 24 | C6: =+B6+100 -> 124
A7: BB10 5/5 | B7: 65 | C7: =+B7+100 -> 165
A8: BB20 | B8: 85 | C8: =+B8+100 -> 185
A9: BPC-157 5mg | B9: 40 | C9: =+B9+100 -> 140 | F9: downloaded
A10: BPC-157 10mg | B10: =45*1.0775 -> 48.4875 | C10: =+B10+100 -> 148.4875 | F10: downloaded
A11: BPC-157 /TB500 20 mg | B11: 150 | C11: =+B11+100 -> 250 | D11: ='BPC+TB500'!J2 -> 0 | E11: ='BPC+TB500'!K2 -> 0 | F11: downloaded | G11: 4/4/26 price now $110 | K11: 238 units (.79 vial) | L11: 420 units (1.4 vials) | M11: 420 units (1.4 vials) | O11: from the start, 2 vials will last almost 8 weeks…..To get from Week 1-12 you need 3.59 vials
A12: BPC-157 20 mg | B12: 155 | C12: =+B12+100 -> 255
A13: Cag 5mg | B13: 65 | C13: =+B13+100 -> 165
A14: Cag 10mg | B14: 105 | C14: =+B14+100 -> 205
A15: CJC-1295/Ipa 5/5 | B15: 60 | C15: =+B15+100 -> 160
A16: DSIP 5mg | B16: 37 | C16: =+B16+100 -> 137 | D16: ='DSIP 5mg'!J2 -> 0 | E16: ='DSIP 5mg'!K2 -> 0 | F16: downloaded | K16: 294 units (1 vial) | L16: 546 units (1.84 vials) | M16: 714 units (2.38 vials) | O16: from the strat 1 vial will last 1 month….To get from Week1 -12 you need 5.22 vials
A17: DSIP 10mg | B17: 47 | C17: =+B17+100 -> 147 | D17: ='DSIP 10mg'!J2 -> 0 | E17: ='DSIP 10mg'!K2 -> 0 | F17: downloaded | K17: 154 units (.51 vials) | L17: 252 units (0.84 vials) | M17: 252 units (0.84 vials) | O17: from the start 2 vials will last approx 6.5 weeks….To get from week 1-12 you need 2.19 vials
A18: Epithalon 5mg | B18: 37 | C18: =+B18+100 -> 137
A19: Epithalon 10mg | B19: 45 | C19: =+B19+100 -> 145 | F19: downloaded
A20: Epithalon 50mg | B20: =70*1.0775 -> 75.425 | C20: =+B20+100 -> 175.425
A21: GHK-CU 50mg | B21: 45 | C21: =+B21+100 -> 145 | D21: ='GHK-CU 50'!K2 -> 0 | E21: ='GHK-CU 50'!L2 -> 0 | F21: downloaded | K21: 168 units (0.56 vials) | L21: 252 units (0.84 vials) | M21: 336 units (1.12 vials) | O21: from the start 2 vials will last 6 weeks….To get from week 1-12 you need 2.52 vials
A22: GHK-CU 100mg | B22: 65 | C22: =+B22+100 -> 165 | F22: downloaded
A23: GLOW 50mg | B23: 65 | C23: =+B23+100 -> 165
A24: GLOW 70mg | B24: 105 | C24: =+B24+100 -> 205 | D24: ='Glow 70'!K2 -> 0 | E24: ='Glow 70'!L2 -> 0 | F24: downloaded | K24: 280 units (0.93 vials) | O24: I only have a 1 month protocol
A25: Glutathione 600mg | B25: 45 | C25: =+B25+100 -> 145 | F25: downloaded
A26: HCG 5000IU | B26: 45 | C26: =+B26+100 -> 145 | F26: downloaded
A27: Hexarelin 10 mg | B27: 70 | C27: =+B27+100 -> 170 | F27: fhgh
A28: HGH 15IU | B28: 65 | C28: =+B28+100 -> 165
A29: HGH 24IU | B29: 77 | C29: =+B29+100 -> 177
A30: HGH 36IU | B30: 90 | C30: =+B30+100 -> 190
A31: Kisspep 10mg | B31: 50 | C31: =+B31+100 -> 150 | D31: =Kissp!K2 -> 0 | E31: =Kissp!L2 -> 0 | F31: downloaded | K31: 126 units (0.42 vials) | L31: 168 units (0.56 vials) | M31: 168 units (0.56 vials) | O31: from the start 1 vial will last 8 weeks….To get from week 1-12 you need 1.54 vials
A32: KLOW 80mg | B32: 125 | C32: =+B32+100 -> 225 | D32: ='KLOW 80'!K2 -> 0 | E32: ='KLOW 80'!L2 -> 0 | F32: email | K32: 308 units (1.03 vials) | L32: 616 units (2.05 vials) | M32: 420 units (1.4 vials) | O32: from the start 1 vial will last the first month…..To get from week 1-12 you need 4.48 vials
A33: Lipo-C w/ B12 | B33: 55 | C33: =+B33+100 -> 155
A34: Melatonin-11 | B34: 45 | C34: =+B34+100 -> 145
A35: Mots-C 10mg | B35: =55*1.0775 -> 59.2625 | C35: =+B35+100 -> 159.2625 | F35: downloaded | K35: 252 units (0.84 vials) | L35: 588 units (1.96 vials) | M35: 840 units (2.8 vials) | O35: from the start 2 vials will last just over 6 weeks….To get from week 1-12 you need 5.6 vials
A36: MT 2 10mg | B36: 45 | C36: =+B36+100 -> 145
A37: NAD+ 1000mg | B37: 75 | C37: =+B37+100 -> 175 | D37: =+'NAD+ Acute'!K2 -> 0 | E37: ='NAD+ Acute'!L2 -> 0 | F37: downloaded
A38: NAD+ 500mg | B38: 55 | C38: =+B38+100 -> 155 | F38: downloaded | K38: Acute: 679 units (2.26 vials) | L38: 840 units (2.8 vials) | M38: 840 units (2.8 vials) | O38: from the start 2.26 vials last 4 weeks…To get from week 1-12 you need 7.86 vials
A39: NAT+ 700mg | B39: =46*1.0775 -> 49.565 | C39: =+B39+50 -> 99.565 | D39: =+B39+50 -> 99.565 | E39: =+B39+30 -> 79.565
A40: Oxytocin 5mg | B40: 45 | C40: =+B40+100 -> 145 | F40: downloaded
A41: PT141 10 mg | B41: 55 | C41: =+B41+100 -> 155 | D41: ='PT-141 10mg'!K2 -> 0 | E41: ='PT-141 10mg'!#REF! -> #REF! | F41: downloaded
...

Sheet FAQ
A1: Frequently asked questions
A3: What is a peptide? Are short chains of amino acids, the same building blocks that make up proteins.
A5: How does it work? Think of a text message in your body - it tells yourself to "stimulate collagen" or " lower inflammation"
A6: It goes straight tho the source, bind to a receptor and triggers a targeted response. They support natural functions. It nudges your system.
A8: How young can you start peptides? Age 15
A10: Should everyone get the same regimine? No. This is not a one size fits all. Different options because of sex, age, athletes vs busy professionals
A11: autoimmune issues vs those chasing peak performance. .
A13: Are peptides synthetic? Yes and No. Some peptides are produced naturally in our body for example insulin (which manages blood sugar),
A14: oxytocin (which influences mood and and bonding), and glucagon (which helps regulate glucose levels). Others are made synthetically in labs
A15: That word- synthetic- tends to scare people but it shouldn’t. Synthetic peptides are not foreign nor dangerous by default. They are simply
A16: Engineered copies of what your body already produces, sometimes with slight modifications to make them more stable, longer -lasing or
A17: more effective.
... A22: Are peptides safe for long term use? Yes, as long a cycled, monitored and respected. Go on, assess, go off, then reassess.

Sheet Whats it for
A1: Wha is it for? | F1: Peptides | G1: Category
A3: Peptide | B3: Column1 | C3: Column4 | D3: Column5
A4: AOD-9604 5mg | B4: Fat Loss and Metabolic support
A5: BAC Water 10ml
A6: BB10 5/5
A7: BB20
A8: BPC-157 5mg | B8: Muscle growth and recovery | C8: Pain relief/gut repair/resilience
A9: BPC-157 10mg | B9: Muscle growth and recovery | C9: Pain relief/gut repair/resilience
A10: BPC-157 /TB500 20 mg | B10: Muscle growth and recovery | C10: Pain relief/gut repair/resilience
A11: BPC-157 20 mg | B11: Muscle growth and recovery | C11: Pain relief/gut repair/resilience
A12: Cag 5mg
A13: Cag 10mg
A14: CJC-1295/Ipa 5/5 | B14: Muscle growth and recovery
A15: DSIP 5mg | B15: Stress and Anxiety | C15: Sleep
A16: DSIP 10mg | B16: Stress and Anxiety | C16: Sleep
A17: Epithalon 5mg | B17: Longevity and cellular renewal | C17: Sleep
A18: Epithalon 10mg | B18: Longevity and cellular renewal | C18: Sleep
A19: Epithalon 50mg | B19: Longevity and cellular renewal | C19: Sleep
A20: GHK-CU 50mg | B20: Skin and aesthetics/Anti -aging
A21: GHK-CU 100mg | B21: Skin and aesthetics/Anti -aging
A22: GLOW 50mg | B22: Skin and aesthetics/Anti -aging
A23: GLOW 70mg | B23: Skin and aesthetics/Anti -aging
A24: Glutathione 600mg
A25: HCG 5000IU
A26: Hexarelin 10 mg
A27: HGH 15IU
A28: HGH 24IU
A29: HGH 36IU
A30: Kisspep 10mg | B30: Hormonal balance 40+
A31: KLOW 80mg | B31: Skin and aesthetics/Anti -aging
A32: Lipo-C w/ B12
A33: Melatonin-11 | B33: Sexual Health
A34: Mots-C 10mg | B34: Fat Loss and Metabolic support | C34: Longevity and cellular renewal | D34: Mitochondrial repair and Energy
A35: MT 2 10mg
A36: NAD+ 1000mg
A37: NAD+ 500mg
A38: Oxytocin 5mg | B38: Stress and Anxiety | C38: Sexual Health
A39: PT141 10 mg | B39: Sexual Health | G39: EXTRAS:
A40: Reta 10mg | B40: Cardiometabolic/lipids/ liver/glucose control/weight management | G40: 29-31 gauge needles,
A41: Reta 20mg | B41: Cardiometabolic/lipids/ liver/glucose control/weight management | G41: sub Q for most
...

Sheet COSTS
A1: Amazon | B1: Cost | C1: With Tax | D1: Cost EACh | F1: COST | G1: Sell
A2: Bubble Wrap (200) | B2: 24.69 | C2: =+B2*1.1 -> 27.159 | D2: =+C2/200 -> 0.135795 | E2: One | F2: 0.12
A3: Mailer (30) | B3: 26.99 | C3: =+B3*1.1 -> 29.689 | D3: =+C3/30 -> 0.98963333 | E3: One | F3: 0.9
A4: Labels (315) | B4: 1.68 | C4: =+B4*1.1 -> 1.848 | D4: =+C4/315 -> 0.0058666667 | E4: One | F4: 0.01
A5: Gift Bag (50) | B5: 17.09 | C5: =+B5*1.1 -> 18.799 | D5: =+C5/50 -> 0.37598 | E5: One | F5: 0.37
A6: Sticker
A7: Pencil Case (6) | B7: 19.93 | C7: =+B7*1.1 -> 21.923 | D7: =+C7/6 -> 3.6538333 | E7: One | F7: 3.32 | G7: 4 | I7: =SUM(F2:F7) -> 4.72
A8: Alcohol Prep (Box of 100) | B8: 3.98 | C8: =+B8*1.1 -> 4.378 | D8: =+C8/100 -> 0.04378 | E8: Box | F8: 3.98 | G8: 5
A9: Orange 0.5ml Syrnge (100) | B9: 21.99 | C9: =+B9*1.1 -> 24.189 | D9: =+C9/100 -> 0.24189 | E9: Ten | F9: =10*0.22 -> 2.2
A10: Blue 3ml Syring (100) | B10: 17.99 | C10: =+B10*1.1 -> 19.789 | D10: =+C10/100 -> 0.19789 | E10: Two | F10: =0.18*2 -> 0.36
A11: Vial Caps (14) | B11: 3.79 | C11: =+B11*1.1 -> 4.169 | D11: =+C11/14 -> 0.29778571 | E11: One | F11: 0.27
A12: Peptide Needles 100 31g 6mm | B12: 9.99 | D12: =+B12/100 -> 0.0999 | E12: Each
A13: BAC 10ml (10) | B13: 30 | C13: =+B13*1.1 -> 33 | D13: =C13/10 -> 3.3 | E13: Each | G13: 10
A14: BAC 3ml (10) | B14: 30 | C14: =+B14*1.1 -> 33 | D14: =+C14/10 -> 3.3 | E14: Each | G14: 10
A15: BACK 30ml (4) | B15: 20.13 | C15: =+B15*1.1 -> 22.143 | D15: =+C15/4 -> 5.53575 | E15: Each | G15: 10
A16: BACK 20ml (6) | B16: 25.99 | C16: =+B16*1.1 -> 28.589 | D16: =+C16/6 -> 4.7648333 | E16: Each | G16: 10
A21: Mackay | B21: Each pen comes with a case and Two cartridges, so thent he patient only need to by the difference in cartridges
A22: Peptide Pen | D22: 45 | E22: Each | G22: 85
A23: 100 cartridges ($0.60 each) | B23: =0.6*100 -> 60 | D23: =+B23/100 -> 0.6 | E23: Each | G23: 2 | H23: each cartridge to the patient | L23: 46114
A24: 100 insulin syringe ( orange?) | B24: 34 | D24: =+B24/100 -> 0.34 | E24: Each
A25: 0.5ml syringe (1000 for $100) | B25: 100 | D25: =+B25/1000 -> 0.1 | E25: Each | L25: 46114
A26: BAC
A28: McKesson
A29: 30ml BAC $24.99 for 75) | B29: 24.99 | D29: =+B29/75 -> 0.3332
B1048566: =SUM(B1:B1048565) -> 473.23 | D1048566: =SUM(D1:D1048565) -> 69.316137

Sheet GLP-3Re
A1: GLP-3Re 20mg | N1: Daily
A2: cost | B2: ='Pep Costs'!B43 -> 140 | E2: Reg Price per VIAL | H2: Per Unruh Reta is going to be a FLAT $350.00 per month for the first 4 months up to 120 units per week for one month. | N2: Every Other Day
A3: BAC | B3: 3.3 | D3: ADD per vial | N3: Weekly
B4: =SUM(B2:B3) -> 143.3 | D4: 100 | E4: =+D4+B4 -> 243.3
A6: Per Unit | B6: =+B4/300 -> 0.47766667
D7: Per Unit | E7: =+E4/300 -> 0.811
A13: CUSTOM PROTOCOL
B15: Frequency of Injection | C15: mcg | D15: Units per Injections | E15: # of Injections | F15: Units Needed | J15: COST | K15: Reg Price | P15: =204.9-195.1 -> 9.8
A16: Week | B16: Every Other Day | D16: 15 | E16: 3 | F16: =+D16*E16 -> 45 | H16: =ROUNDUP(F20,0) -> 210 | I16: Units | J16: =+B6*F20 -> 100.31 | K16: =+F20*E7 -> 170.31
A17: Week | B17: Every Other Day | D17: 15 | E17: 4 | F17: =+D17*E17 -> 60 | H17: =E20 -> 14 | I17: Syringe | J17: =+H17*0.24 -> 3.36
A18: Week | B18: Every Other Day | D18: 15 | E18: 3 | F18: =+D18*E18 -> 45 | H18: =E20 -> 14 | I18: Alochol Prep | J18: =0.05*H18 -> 0.7 | M18: Profit | N18: =+K20-J20 -> 66.63
A19: Week | B19: Every Other Day | D19: 15 | E19: 4 | F19: =+D19*E19 -> 60 | H19: 0 | I19: Case | J19: =H19*3.65 -> 0
E20: =SUM(E16:E19) -> 14 | F20: =SUM(F16:F19) -> 210 | J20: =SUM(J16:J19) -> 104.37 | K20: =ROUNDUP(SUM(K16:K19),0) -> 171
F21: =+F20/300 -> 0.7 | I21: Per Unit | J21: =+J20/H16 -> 0.497 | K21: =+K20/H16 -> 0.81428571
A27: Month 1 | B27: Frequency of Injection | C27: mcg | D27: Units per Injections | E27: # of Injections | F27: Units Needed
A28: 1st Injection | B28: Once | C28: 350mcg | D28: 5 | E28: 1 | F28: =+D28*E28 -> 5 | J28: COST | K28: Reg Price | Q28: week 1 | R28: 10 | T28: 0.7mg =700mcg 14 20mg/ml = 10 units
A29: 2nd 3-4 days | B29: Once | C29: 350mcg | D29: 5 | E29: 1 | F29: =+D29*E29 -> 5 | H29: =ROUNDUP(F33,0) -> 40 | I29: Units | J29: =+B6*F33 -> 19.106667 | K29: =F33*E7 -> 32.44 | Q29: week 2 | R29: 10
A30: Week 2 | B30: Weekly | C30: 700mcg | D30: 10 | E30: =IF(B30="Daily",7, IF(B30="Weekly",1, IF(B30="Every Other Day",4,""))) -> 1 | F30: =+D30*E30 -> 10 | H30: =E33 -> 5 | I30: Syringe | J30: =H30*0.24 -> 1.2 | Q30: week 3 | R30: 20
A31: Week 3 | B31: Weekly | C31: 700mcg | D31: 10 | E31: =IF(B31="Daily",7, IF(B31="Weekly",1, IF(B31="Every Other Day",4,""))) -> 1 | F31: =+D31*E31 -> 10 | H31: =H30 -> 5 | I31: Alochol Prep | J31: =+H31*0.05 -> 0.25 | Q31: week 4 | R31: 20
A32: Week 4 | B32: Weekly | C32: 700mcg | D32: 10 | E32: =IF(B32="Daily",7, IF(B32="Weekly",1, IF(B32="Every Other Day",4,""))) -> 1 | F32: =+D32*E32 -> 10 | H32: 1 | I32: Case | J32: =H32*3.65 -> 3.65 | M32: Profit | N32: =+K33-J33 -> 325.79333
E33: =SUM(E28:E32) -> 5 | F33: =SUM(F28:F32) -> 40 | J33: =SUM(J29:J32) -> 24.206667 | K33: 350
E34: Number of vials = | F34: =+F33/300 -> 0.13333333 | I34: Per Unit | J34: =+J33/H29 -> 0.60516667 | K34: =+K33/H29 -> 8.75
A38: Month 2 | B38: Frequency of Injection | C38: mcg | D38: Units per Injections | E38: # of Injections | F38: Units Needed | J38: COST | K38: Reg Price
A39: Week 5 | B39: Weekly | C39: 1350 | D39: 20 | E39: =IF(B39="Daily",7, IF(B39="Weekly",1, IF(B39="Every Other Day",4,""))) -> 1 | F39: =+D39*E39 -> 20 | H39: =ROUNDUP(F43,0) -> 80 | I39: Units | J39: =+B6*F43 -> 38.213333 | K39: =+F43*E7 -> 64.88
A40: Week 6 | B40: Weekly | C40: 1350 | D40: 20 | E40: =IF(B40="Daily",7, IF(B40="Weekly",1, IF(B40="Every Other Day",4,""))) -> 1 | F40: =+D40*E40 -> 20 | H40: =E43 -> 4 | I40: Syringe | J40: =H40*0.24 -> 0.96
A41: Week 7 | B41: Weekly | C41: 1350 | D41: 20 | E41: =IF(B41="Daily",7, IF(B41="Weekly",1, IF(B41="Every Other Day",4,""))) -> 1 | F41: =+D41*E41 -> 20 | H41: =E43 -> 4 | I41: Alochol Prep | J41: =+H41*0.05 -> 0.2
A42: Week 8 | B42: Weekly | C42: 1350 | D42: 20 | E42: =IF(B42="Daily",7, IF(B42="Weekly",1, IF(B42="Every Other Day",4,""))) -> 1 | F42: =+D42*E42 -> 20 | H42: 0 | I42: Case | J42: =H42*3.65 -> 0
E43: =SUM(E39:E42) -> 4 | F43: =SUM(F39:F42) -> 80 | J43: =SUM(J39:J42) -> 39.373333 | K43: =K33 -> 350 | M43: Profit | N43: =+K43-J43 -> 310.62667
E44: Number of vials = | F44: =+F43/300 -> 0.26666667 | I44: Per Unit | J44: =+J43/H39 -> 0.49216667 | K44: =+K43/H39 -> 4.375
A50: Month 3 | B50: Frequency of Injection | C50: mcg | D50: Units per Injections | E50: # of Injections | F50: Units Needed | J50: COST | K50: Reg Price | S50: =30*0.85 -> 25.5
A51: Week 9 | B51: Weekly | C51: 2000 | D51: 30 | E51: =IF(B51="Daily",7, IF(B51="Weekly",1, IF(B51="Every Other Day",4,""))) -> 1 | F51: =+D51*E51 -> 30 | H51: =ROUNDUP(F55,0) -> 120 | I51: Units | J51: =+B6*F55 -> 57.32 | K51: =+F55*E7 -> 97.32
A52: week 10 | B52: Weekly | C52: 2000 | D52: 30 | E52: =IF(B52="Daily",7, IF(B52="Weekly",1, IF(B52="Every Other Day",4,""))) -> 1 | F52: =+D52*E52 -> 30 | H52: =E55 -> 4 | I52: Syringe | J52: =+H52*0.24 -> 0.96
A53: Week 11 | B53: Weekly | C53: 2000 | D53: 30 | E53: =IF(B53="Daily",7, IF(B53="Weekly",1, IF(B53="Every Other Day",4,""))) -> 1 | F53: =+D53*E53 -> 30 | H53: =E55 -> 4 | I53: Alochol Prep | J53: =H53*0.05 -> 0.2
A54: Week 12 | B54: Weekly | C54: 2000 | D54: 30 | E54: =IF(B54="Daily",7, IF(B54="Weekly",1, IF(B54="Every Other Day",4,""))) -> 1 | F54: =+D54*E54 -> 30 | H54: 0 | I54: Case | J54: =H54*3.65 -> 0
E55: =SUM(E51:E54) -> 4 | F55: =SUM(F51:F54) -> 120 | J55: =SUM(J51:J54) -> 58.48 | K55: =K33 -> 350 | M55: Profit | N55: =+K55-J55 -> 291.52
E56: Number of vials = | F56: =+F55/300 -> 0.4 | I56: Per Unit | J56: =+J55/H51 -> 0.48733333 | K56: =+K55/H51 -> 2.9166667
A60: Month 4 | B60: Frequency of Injection | C60: mcg | D60: Units per Injections | E60: # of Injections | F60: Units Needed | J60: COST | K60: Reg Price | P60: =0.2+0.27+0.33+0.4 -> 1.2
A61: Week 13 | B61: Weekly | C61: 2650 | D61: 40 | E61: =IF(B61="Daily",7, IF(B61="Weekly",1, IF(B61="Every Other Day",4,""))) -> 1 | F61: =+D61*E61 -> 40 | H61: =ROUNDUP(F65,0) -> 160 | I61: Units | J61: =F65*B6 -> 76.426667 | K61: =+F65*E7 -> 129.76
A62: Week 14 | B62: Weekly | C62: 2650 | D62: 40 | E62: =IF(B62="Daily",7, IF(B62="Weekly",1, IF(B62="Every Other Day",4,""))) -> 1 | F62: =+D62*E62 -> 40 | H62: =E65 -> 4 | I62: Syringe | J62: =+H62*0.24 -> 0.96
A63: Week 15 | B63: Weekly | C63: 2650 | D63: 40 | E63: =IF(B63="Daily",7, IF(B63="Weekly",1, IF(B63="Every Other Day",4,""))) -> 1 | F63: =+D63*E63 -> 40 | H63: =E65 -> 4 | I63: Alochol Prep | J63: =H63*0.05 -> 0.2
...

Sheet BPC+TB500
A1: BPC157 + TB500 20mg | N1: Daily
B2: ='Pep Costs'!B11 -> 150 | C2: cost | N2: Every Other Day
B3: 3.3 | C3: BAC | N3: Weekly
B4: 15 | C4: (30) Pen Needles, up to 3 Cartridges, (30)Alcohol Prep | F4: ADD per vial | G4: Reg Price | N4: Monthly
B5: =SUM(B2:B4) -> 168.3 | F5: 100 | G5: =+F5+B5 -> 268.3
A7: Per Unit | B7: =+B5/300 -> 0.561 | F7: Per Unit | G7: =+G5/300 -> 0.89433333
A13: CUSTOM PROTOCOL | K13: Reg Price
H14: =ROUNDUP(F20,0) -> 240 | I14: Units | J14: =+B7*F20 -> 134.64 | K14: =+F20*G7 -> 214.64
B15: Frequency of Injection | C15: mcg | D15: Units per Injections | E15: # of Injections | F15: Units Needed | H15: 0 | I15: Pen | J15: =+H15*45 -> 0
A16: Week | B16: Every Other Day | C16: 1000 | D16: 15 | E16: =IF(B16="Daily",7, IF(B16="Weekly",1, IF(B16="Every Other Day",4,""))) -> 4 | F16: =+D16*E16 -> 60 | H16: =IF(E20>=25, E20+2, E20+1) -> 17 | I16: Pen Needles
A17: Week | B17: Every Other Day | C17: 1000 | D17: 15 | E17: =IF(B17="Daily",7, IF(B17="Weekly",1, IF(B17="Every Other Day",4,""))) -> 4 | F17: =+D17*E17 -> 60 | H17: =ROUNDUP(F21,0) -> 1 | I17: Cartridges
A18: Week | B18: Every Other Day | C18: 1000 | D18: 15 | E18: =IF(B18="Daily",7, IF(B18="Weekly",1, IF(B18="Every Other Day",4,""))) -> 4 | F18: =+D18*E18 -> 60 | H18: =H16 -> 17 | I18: Alochol Prep
A19: Week | B19: Every Other Day | C19: 1000 | D19: 15 | E19: =IF(B19="Daily",7, IF(B19="Weekly",1, IF(B19="Every Other Day",4,""))) -> 4 | F19: =+D19*E19 -> 60 | H19: 0 | I19: Case | J19: =H19*3.65 -> 0
E20: =SUM(E16:E19) -> 16 | F20: =SUM(F16:F19) -> 240 | J20: =SUM(J14:J19) -> 134.64 | K20: =ROUNDUP(SUM(K14:K19),0) -> 215 | M20: Profit | N20: =+K20-J20 -> 80.36
E21: Number of Cartridges needed | F21: =+F20/300 -> 0.8 | I21: Per Unit | J21: =+J20/H14 -> 0.561 | K21: =+K20/H14 -> 0.89583333
J30: COST | K30: Reg Price
H31: =ROUNDUP(F37,0) -> 238 | I31: Units | J31: =F37*B7 -> 133.518 | K31: =+F37*G7 -> 212.85133
A32: Month 1 | B32: Frequency of Injection | C32: mcg | D32: Units per Injections | E32: # of Injections | F32: Units Needed | H32: 1 | I32: Pen | J32: =+H32*45 -> 45 | K32: =H32*85 -> 85
A33: Week 1 | B33: Daily | C33: 500 | D33: 7 | E33: =IF(B33="Daily",7, IF(B33="Weekly",1, IF(B33="Every Other Day",4,""))) -> 7 | F33: =+D33*E33 -> 49 | H33: =IF(E37>=25, E37+2, E37+1) -> 30 | I33: Pen Needles
A34: Week 2 | B34: Daily | C34: 500 | D34: 7 | E34: =IF(B34="Daily",7, IF(B34="Weekly",1, IF(B34="Every Other Day",4,""))) -> 7 | F34: =+D34*E34 -> 49 | H34: =ROUNDUP(F38,0) -> 1 | I34: Cartridges
A35: Week 3 | B35: Daily | C35: 666 | D35: 10 | E35: =IF(B35="Daily",7, IF(B35="Weekly",1, IF(B35="Every Other Day",4,""))) -> 7 | F35: =+D35*E35 -> 70 | H35: =H33 -> 30 | I35: Alochol Prep
A36: Week 4 | B36: Daily | C36: 666 | D36: 10 | E36: =IF(B36="Daily",7, IF(B36="Weekly",1, IF(B36="Every Other Day",4,""))) -> 7 | F36: =+D36*E36 -> 70 | H36: 1 | I36: Case | J36: =H36*3.65 -> 3.65
E37: =SUM(E33:E36) -> 28 | F37: =SUM(F33:F36) -> 238 | J37: =SUM(J31:J36) -> 182.168 | K37: =ROUNDUP(SUM(K31:K36),0) -> 298 | M37: Profit | N37: =+K37-J37 -> 115.832
E38: Number of Cartridges needed | F38: =+F37/300 -> 0.79333333 | I38: Per Unit | J38: =+J37/H31 -> 0.76541176 | K38: =+K37/H31 -> 1.2521008
J43: COST | K43: Reg Price
H44: =ROUNDUP(F50,0) -> 420 | I44: Units | J44: =+B7*F50 -> 235.62 | K44: =+F50*G7 -> 375.62
A45: Month 2 | B45: Frequency of Injection | C45: mcg | D45: Units per Injections | E45: # of Injections | F45: Units Needed | H45: 0 | I45: Pen | J45: =+H45*45 -> 0 | K45: =+H45*85 -> 0
A46: Week 5 | B46: Daily | C46: 1000 | D46: 15 | E46: =IF(B46="Daily",7, IF(B46="Weekly",1, IF(B46="Every Other Day",4,""))) -> 7 | F46: =+D46*E46 -> 105 | H46: =IF(E50>=25, E50+2, E50+1) -> 30 | I46: Pen Needles
A47: Week 6 | B47: Daily | C47: 1000 | D47: 15 | E47: =IF(B47="Daily",7, IF(B47="Weekly",1, IF(B47="Every Other Day",4,""))) -> 7 | F47: =+D47*E47 -> 105 | H47: =ROUNDUP(F51,0) -> 2 | I47: Cartridges
A48: Week 7 | B48: Daily | C48: 1000 | D48: 15 | E48: =IF(B48="Daily",7, IF(B48="Weekly",1, IF(B48="Every Other Day",4,""))) -> 7 | F48: =+D48*E48 -> 105 | H48: =H46 -> 30 | I48: Alochol Prep
A49: Week 8 | B49: Daily | C49: 1000 | D49: 15 | E49: =IF(B49="Daily",7, IF(B49="Weekly",1, IF(B49="Every Other Day",4,""))) -> 7 | F49: =+D49*E49 -> 105 | H49: 0 | I49: Case | J49: =H49*3.65 -> 0
E50: =SUM(E46:E49) -> 28 | F50: =SUM(F46:F49) -> 420 | J50: =SUM(J44:J49) -> 235.62 | K50: =ROUNDUP(SUM(K44:K49),0) -> 376 | M50: Profit | N50: =+K50-J50 -> 140.38
E51: Number of Cartridges needed | F51: =+F50/300 -> 1.4 | I51: Per Unit | J51: =+J50/H44 -> 0.561 | K51: =+K50/H44 -> 0.8952381
J55: COST | K55: Reg Price
H56: =ROUNDUP(F62,0) -> 420 | I56: Units | J56: =+B7*F62 -> 235.62 | K56: =+F62*G7 -> 375.62
A57: Month 3 | B57: Frequency of Injection | C57: mcg | D57: Units per Injections | E57: # of Injections | F57: Units Needed | H57: 0 | I57: Pen | J57: =+H57*45 -> 0 | K57: =+H57*85 -> 0
A58: Week 9 | B58: Daily | C58: 1000 | D58: 15 | E58: =IF(B58="Daily",7, IF(B58="Weekly",1, IF(B58="Every Other Day",4,""))) -> 7 | F58: =+D58*E58 -> 105 | H58: =IF(E62>=25, E62+2, E62+1) -> 30 | I58: Pen Needles
A59: Week 10 | B59: Daily | C59: 1000 | D59: 15 | E59: =IF(B59="Daily",7, IF(B59="Weekly",1, IF(B59="Every Other Day",4,""))) -> 7 | F59: =+D59*E59 -> 105 | H59: =ROUNDUP(F63,0) -> 2 | I59: Cartridges
A60: Week 11 | B60: Daily | C60: 1000 | D60: 15 | E60: =IF(B60="Daily",7, IF(B60="Weekly",1, IF(B60="Every Other Day",4,""))) -> 7 | F60: =+D60*E60 -> 105 | H60: =H58 -> 30 | I60: Alochol Prep
A61: Week 12 | B61: Daily | C61: 1000 | D61: 15 | E61: =IF(B61="Daily",7, IF(B61="Weekly",1, IF(B61="Every Other Day",4,""))) -> 7 | F61: =+D61*E61 -> 105 | H61: 0 | I61: Case | J61: =H61*3.65 -> 0
...

Sheet Wolv Slow Tit
A1: BPC157 + TB500 20mg (Slow Titration) | N1: Daily
B2: ='Pep Costs'!B11 -> 150 | C2: cost | F2: Add per vial | G2: Reg Price | N2: Every Other Day
B3: 3.3 | C3: BAC | F3: 100 | G3: =+F3+B5 -> 268.3 | N3: Weekly
B4: 15 | C4: (30) Pen Needles, Cartridges, Alcohol Prep
B5: =SUM(B2:B4) -> 168.3
F6: Per Unit | G6: =+G3/300 -> 0.89433333
A7: Per Unit | B7: =+B5/300 -> 0.561
K11: Reg Price
H12: =ROUNDUP(F18,0) -> 136 | I12: Units | J12: =F18*B7 -> 76.296 | K12: =+F18*G6 -> 121.62933
A13: Month 1 | B13: Frequency of Injection | C13: mcg | D13: Units per Injections | E13: # of Injections | F13: Units Needed | H13: 0 | I13: Pen | J13: =+H13*45 -> 0 | K13: =H13*85 -> 0
A14: Week 1 | B14: Every Other Day | C14: 500 | D14: 7 | E14: =IF(B14="Daily",7, IF(B14="Weekly",1, IF(B14="Every Other Day",4,""))) -> 4 | F14: =+D14*E14 -> 28 | H14: =IF(E18>=25, E18+2, E18+1) -> 17 | I14: Pen Needles
A15: Week 2 | B15: Every Other Day | C15: 500 | D15: 7 | E15: =IF(B15="Daily",7, IF(B15="Weekly",1, IF(B15="Every Other Day",4,""))) -> 4 | F15: =+D15*E15 -> 28 | H15: =ROUNDUP(F19,0) -> 1 | I15: Cartridges
A16: Week 3 | B16: Every Other Day | C16: 666 | D16: 10 | E16: =IF(B16="Daily",7, IF(B16="Weekly",1, IF(B16="Every Other Day",4,""))) -> 4 | F16: =+D16*E16 -> 40 | H16: =H14 -> 17 | I16: Alochol Prep
A17: Week 4 | B17: Every Other Day | C17: 666 | D17: 10 | E17: =IF(B17="Daily",7, IF(B17="Weekly",1, IF(B17="Every Other Day",4,""))) -> 4 | F17: =+D17*E17 -> 40 | H17: 1 | I17: Case | J17: =H17*3.65 -> 3.65
E18: =SUM(E14:E17) -> 16 | F18: =SUM(F14:F17) -> 136 | J18: =SUM(J12:J17) -> 79.946 | K18: =ROUNDUP(SUM(K12:K17),0) -> 122 | M18: Profit | N18: =+K18-J18 -> 42.054
E19: Number of Cartridges needed | F19: =+F18/300 -> 0.45333333 | I19: Per Unit | J19: =+J18/H12 -> 0.58783824 | K19: =+K18/H12 -> 0.89705882
K23: Reg Price
H24: =ROUNDUP(F30,0) -> 240 | I24: Units | J24: =+B7*F30 -> 134.64 | K24: =+F30*G6 -> 214.64
A25: Month 2 | B25: Frequency of Injection | C25: mcg | D25: Units per Injections | E25: # of Injections | F25: Units Needed | H25: 0 | I25: Pen | J25: =+H25*45 -> 0 | K25: =+H25*85 -> 0
A26: Week 5 | B26: Every Other Day | C26: 1000 | D26: 15 | E26: =IF(B26="Daily",7, IF(B26="Weekly",1, IF(B26="Every Other Day",4,""))) -> 4 | F26: =+D26*E26 -> 60 | H26: =IF(E30>=25, E30+2, E30+1) -> 17 | I26: Pen Needles
A27: Week 6 | B27: Every Other Day | C27: 1000 | D27: 15 | E27: =IF(B27="Daily",7, IF(B27="Weekly",1, IF(B27="Every Other Day",4,""))) -> 4 | F27: =+D27*E27 -> 60 | H27: =ROUNDUP(F31,0) -> 1 | I27: Cartridges
A28: Week 7 | B28: Every Other Day | C28: 1000 | D28: 15 | E28: =IF(B28="Daily",7, IF(B28="Weekly",1, IF(B28="Every Other Day",4,""))) -> 4 | F28: =+D28*E28 -> 60 | H28: =H26 -> 17 | I28: Alochol Prep
A29: Week 8 | B29: Every Other Day | C29: 1000 | D29: 15 | E29: =IF(B29="Daily",7, IF(B29="Weekly",1, IF(B29="Every Other Day",4,""))) -> 4 | F29: =+D29*E29 -> 60 | H29: 0 | I29: Case | J29: =H29*3.65 -> 0
E30: =SUM(E26:E29) -> 16 | F30: =SUM(F26:F29) -> 240 | J30: =SUM(J24:J29) -> 134.64 | K30: =ROUNDUP(SUM(K24:K29),0) -> 215 | M30: Profit | N30: =+K30-J30 -> 80.36
E31: Number of Cartridges needed | F31: =+F30/300 -> 0.8 | I31: Per Unit | J31: =+J30/H24 -> 0.561 | K31: =+K30/H24 -> 0.89583333
K35: Reg Price
H36: =ROUNDUP(F42,0) -> 240 | I36: Units | J36: =+B7*F42 -> 134.64 | K36: =+F42*G6 -> 214.64
A37: Month 3 | B37: Frequency of Injection | C37: mcg | D37: Units per Injections | E37: # of Injections | F37: Units Needed | H37: 0 | I37: Pen | J37: =+H37*45 -> 0 | K37: =+H37*85 -> 0
A38: Week 9 | B38: Every Other Day | C38: 1000 | D38: 15 | E38: =IF(B38="Daily",7, IF(B38="Weekly",1, IF(B38="Every Other Day",4,""))) -> 4 | F38: =+D38*E38 -> 60 | H38: =IF(E42>=25, E42+2, E42+1) -> 17 | I38: Pen Needles
A39: Week 10 | B39: Every Other Day | C39: 1000 | D39: 15 | E39: =IF(B39="Daily",7, IF(B39="Weekly",1, IF(B39="Every Other Day",4,""))) -> 4 | F39: =+D39*E39 -> 60 | H39: =ROUNDUP(F43,0) -> 1 | I39: Cartridges
A40: Week 11 | B40: Every Other Day | C40: 1000 | D40: 15 | E40: =IF(B40="Daily",7, IF(B40="Weekly",1, IF(B40="Every Other Day",4,""))) -> 4 | F40: =+D40*E40 -> 60 | H40: =H38 -> 17 | I40: Alochol Prep
A41: Week 12 | B41: Every Other Day | C41: 1000 | D41: 15 | E41: =IF(B41="Daily",7, IF(B41="Weekly",1, IF(B41="Every Other Day",4,""))) -> 4 | F41: =+D41*E41 -> 60 | H41: 0 | I41: Case | J41: =H41*3.65 -> 0
E42: =SUM(E38:E41) -> 16 | F42: =SUM(F38:F41) -> 240 | J42: =SUM(J36:J41) -> 134.64 | K42: =ROUNDUP(SUM(K36:K41),0) -> 215 | M42: Profit | N42: =+K42-J42 -> 80.36
E43: Number of Cartridges needed | F43: =+F42/300 -> 0.8 | I43: Per Unit | J43: =+J42/H36 -> 0.561 | K43: =+K42/H36 -> 0.89583333
A47: Month 4
A48: Week 13-16 | B48: The patient needs to have a conversation with Unruh as they will most likely take this month OFF.
B49: When the patient returns they may continue to match Week 9-12 or go on a custome protocol
A56: Over 10 months
D57: Sell the bottle?
A58: If we sell exactly what the need: | D58: how many vials do you need for 10 months?
...

Sheet Wolv Maintenance
A1: BPC157 + TB500 20mg (Maintenance) | N1: Daily
B2: ='Pep Costs'!B11 -> 150 | C2: cost | N2: Every Other Day
B3: 3.3 | C3: BAC | N3: Weekly
B4: 15 | C4: (30) Pen Needles, Cartridges, Alcohol Prep | F4: Add per vial | G4: Reg Price
B5: =SUM(B2:B4) -> 168.3 | F5: 100 | G5: =SUM(B5:F5) -> 268.3
A7: Per Unit | B7: =+B5/300 -> 0.561 | F7: Per Unit | G7: =+G5/300 -> 0.89433333
K11: Reg Price
H12: =ROUNDUP(F18,0) -> 128 | I12: Units | J12: =F18*B7 -> 71.808 | K12: =+F18*G7 -> 114.47467
A13: Month 1 | B13: Frequency of Injection | C13: mcg | D13: Units per Injections | E13: # of Injections | F13: Units Needed | H13: 0 | I13: Pen | J13: =+H13*45 -> 0 | K13: =+H13*85 -> 0
A14: Week 1 | B14: Every Other Day | C14: 500 | D14: 8 | E14: =IF(B14="Daily",7, IF(B14="Weekly",1, IF(B14="Every Other Day",4,""))) -> 4 | F14: =+D14*E14 -> 32 | H14: =IF(E18>=25, E18+2, E18+1) -> 17 | I14: Pen Needles
A15: Week 2 | B15: Every Other Day | C15: 500 | D15: 8 | E15: =IF(B15="Daily",7, IF(B15="Weekly",1, IF(B15="Every Other Day",4,""))) -> 4 | F15: =+D15*E15 -> 32 | H15: =ROUNDUP(F19,0) -> 1 | I15: Cartridges
A16: Week 3 | B16: Every Other Day | C16: 500 | D16: 8 | E16: =IF(B16="Daily",7, IF(B16="Weekly",1, IF(B16="Every Other Day",4,""))) -> 4 | F16: =+D16*E16 -> 32 | H16: =H14 -> 17 | I16: Alochol Prep
A17: Week 4 | B17: Every Other Day | C17: 500 | D17: 8 | E17: =IF(B17="Daily",7, IF(B17="Weekly",1, IF(B17="Every Other Day",4,""))) -> 4 | F17: =+D17*E17 -> 32 | H17: 1 | I17: Case | J17: =H17*3.65 -> 3.65
E18: =SUM(E14:E17) -> 16 | F18: =SUM(F14:F17) -> 128 | J18: =SUM(J12:J17) -> 75.458 | K18: 150 | M18: Profit | N18: =+K18-J18 -> 74.542
E19: Number of Cartridges needed | F19: =+F18/300 -> 0.42666667 | I19: Per Unit | J19: =+J18/H12 -> 0.58951563 | K19: =+K18/H12 -> 1.171875
A26: Over 10 months
D27: Sell the bottle?
A28: If we sell exactly what the need: | D28: how many vials do you need for 10 months?
A29: based on Week 1-4 | E29: Units per month | F29: =F18 -> 128
A30: Monthly Profit | B30: =N18 -> 74.542 | E30: Months | F30: 10
F31: =+F30*F29 -> 1280 | G31: Unts needed
E32: Number of vials (div by 300) | F32: =ROUNDUP((F31/300),0) -> 5
E33: $100 per vial | F33: =+F32*100 -> 500
E35: Average montly profit | F35: =+F33/10 -> 50
A44: What is the largest disocunt/Sale we can offer on Peptides? | G44: What is the largest disocunt/Sale we can offer on Peptides?
A45: Based on highest dosage: | G45: Based on FIRSTS MONTH
B47: Pt Price | C47: Cost | D47: Profit | H47: Pt Price | I47: Cost | J47: Profit
A48: 0 | B48: =K18 -> 150 | C48: =J18 -> 75.458 | D48: =+B48-C48 -> 74.542 | G48: 0 | H48: =K18 -> 150 | I48: =J18 -> 75.458 | J48: =+H48-I48 -> 74.542
A49: 0.1 | B49: =0.9*B48 -> 135 | C49: =C48 -> 75.458 | D49: =+B49-C49 -> 59.542 | G49: 0.1 | H49: =0.9*H48 -> 135 | I49: =I48 -> 75.458 | J49: =+H49-I49 -> 59.542
A50: 0.15 | B50: =+B48*0.85 -> 127.5 | C50: =C49 -> 75.458 | D50: =+B50-C50 -> 52.042 | G50: 0.15 | H50: =+H48*0.85 -> 127.5 | I50: =I49 -> 75.458 | J50: =+H50-I50 -> 52.042
A51: 0.2 | B51: =0.8*B48 -> 120 | C51: =C50 -> 75.458 | D51: =+B51-C51 -> 44.542 | G51: 0.2 | H51: =0.8*H48 -> 120 | I51: =I50 -> 75.458 | J51: =+H51-I51 -> 44.542
A52: 0.25 | B52: =0.75*B48 -> 112.5 | C52: =C51 -> 75.458 | D52: =+B52-C52 -> 37.042 | G52: 0.25 | H52: =0.755*H48 -> 113.25 | I52: =I51 -> 75.458 | J52: =+H52-I52 -> 37.792

Sheet ARA290
A1: ARA-290 10mg | O1: Daily
B2: 59.26 | C2: cost | O2: Every Other Day
B3: 3.3 | C3: BAC | O3: Weekly
B4: 15 | C4: (30) Pen Needles, Cartridges, Alcohol Prep | F4: Add per vial | G4: Reg Price
B5: =SUM(B2:B4) -> 77.56 | F5: 35 | G5: =+F5+B5 -> 112.56
A7: Per Unit | B7: =+B5/300 -> 0.25853333 | F7: Per Unit | G7: =+G5/300 -> 0.3752
A13: CUSTOM PROTOCOL | K13: Reg Price
H14: =ROUNDUP(F20,0) -> 285 | I14: Units | J14: =+B7*F20 -> 73.682 | K14: =+F20*G7 -> 106.932
B15: Frequency of Injection | C15: mcg | D15: Units per Injections | E15: # of Injections | F15: Units Needed | H15: 1 | I15: Pen | J15: =+H15*45 -> 45 | K15: =+H15*85 -> 85
A16: Week | B16: Daily | C16: 500 | D16: 15 | E16: =IF(B16="Daily",7, IF(B16="Weekly",1, IF(B16="Every Other Day",4,""))) -> 7 | F16: =+D16*E16 -> 105 | H16: =IF(E20>=25, E20+2, E20+1) -> 20 | I16: Pen Needles
A17: Week | B17: Every Other Day | C17: 500 | D17: 15 | E17: =IF(B17="Daily",7, IF(B17="Weekly",1, IF(B17="Every Other Day",4,""))) -> 4 | F17: =+D17*E17 -> 60 | H17: =ROUNDUP(F21,0) -> 1 | I17: Cartridges
A18: Week | B18: Daily | C18: 500 | D18: 15 | E18: =IF(B18="Daily",7, IF(B18="Weekly",1, IF(B18="Every Other Day",4,""))) -> 7 | F18: =+D18*E18 -> 105 | H18: =H16 -> 20 | I18: Alochol Prep
A19: Week | B19: Weekly | C19: 500 | D19: 15 | E19: =IF(B19="Daily",7, IF(B19="Weekly",1, IF(B19="Every Other Day",4,""))) -> 1 | F19: =+D19*E19 -> 15 | H19: 0 | I19: Case | J19: =H19*3.65 -> 0
E20: =SUM(E16:E19) -> 19 | F20: =SUM(F16:F19) -> 285 | J20: =SUM(J14:J19) -> 118.682 | K20: =ROUNDUP(SUM(K14:K19),0) -> 192 | M20: Profit | N20: =+K20-J20 -> 73.318
E21: Number of Cartridges needed | F21: =+F20/300 -> 0.95 | I21: Per Unit | J21: =+J20/H14 -> 0.41642807 | K21: =+K20/H14 -> 0.67368421
K26: Reg Price
H27: =ROUNDUP(F33,0) -> 1838 | I27: Units | J27: =F33*B7 -> 475.055 | K27: =+F33*G7 -> 689.43
A28: Month 1 | B28: Frequency of Injection | C28: mcg | D28: Units per Injections | E28: # of Injections | F28: Units Needed | H28: 0 | I28: Pen | J28: =+H28*45 -> 0 | K28: =H28*85 -> 0
A29: Week 1 | B29: Daily | C29: 2000 | D29: 37.5 | E29: =IF(B29="Daily",7, IF(B29="Weekly",1, IF(B29="Every Other Day",4,""))) -> 7 | F29: =+D29*E29 -> 262.5 | H29: =IF(E33>=25, E33+2, E33+1) -> 30 | I29: Pen Needles
A30: Week 2 | B30: Daily | C30: 4000 | D30: 75 | E30: =IF(B30="Daily",7, IF(B30="Weekly",1, IF(B30="Every Other Day",4,""))) -> 7 | F30: =+D30*E30 -> 525 | H30: =ROUNDUP(F34,0) -> 7 | I30: Cartridges | J30: =(H30-2)*0.6 -> 3 | K30: =(H30-2) -> 5
A31: Week 3 | B31: Daily | C31: 4000 | D31: 75 | E31: =IF(B31="Daily",7, IF(B31="Weekly",1, IF(B31="Every Other Day",4,""))) -> 7 | F31: =+D31*E31 -> 525 | H31: =H29 -> 30 | I31: Alochol Prep
A32: Week 4 | B32: Daily | C32: 4000 | D32: 75 | E32: =IF(B32="Daily",7, IF(B32="Weekly",1, IF(B32="Every Other Day",4,""))) -> 7 | F32: =+D32*E32 -> 525 | H32: 1 | I32: Case | J32: =H32*3.65 -> 3.65
E33: =SUM(E29:E32) -> 28 | F33: =SUM(F29:F32) -> 1837.5 | J33: =SUM(J27:J32) -> 481.705 | K33: =ROUNDUP(SUM(K27:K32),0) -> 695 | M33: Profit | N33: =+K33-J33 -> 213.295
E34: Number of Cartridges needed | F34: =+F33/300 -> 6.125 | I34: Per Unit | J34: =+J33/H27 -> 0.26208107 | K34: =+K33/H27 -> 0.3781284
K38: Reg Price
H39: =ROUNDUP(F45,0) -> 2100 | I39: Units | J39: =+B7*F45 -> 542.92 | K39: =+F45*G7 -> 787.92
A40: Month 2 | B40: Frequency of Injection | C40: mcg | D40: Units per Injections | E40: # of Injections | F40: Units Needed | H40: 0 | I40: Pen | J40: =+H40*45 -> 0 | K40: =+H40*85 -> 0
A41: Week 5 | B41: Daily | C41: 4000 | D41: 75 | E41: =IF(B41="Daily",7, IF(B41="Weekly",1, IF(B41="Every Other Day",4,""))) -> 7 | F41: =+D41*E41 -> 525 | H41: =IF(E45>=25, E45+2, E45+1) -> 30 | I41: Pen Needles
A42: Week 6 | B42: Daily | C42: 4000 | D42: 75 | E42: =IF(B42="Daily",7, IF(B42="Weekly",1, IF(B42="Every Other Day",4,""))) -> 7 | F42: =+D42*E42 -> 525 | H42: =ROUNDUP(F46,0) -> 7 | I42: Cartridges | J42: =H42*0.6 -> 4.2 | K42: =+H42 -> 7
A43: Week 7 | B43: Daily | C43: 4000 | D43: 75 | E43: =IF(B43="Daily",7, IF(B43="Weekly",1, IF(B43="Every Other Day",4,""))) -> 7 | F43: =+D43*E43 -> 525 | H43: =H41 -> 30 | I43: Alochol Prep
A44: Week 8 | B44: Daily | C44: 4000 | D44: 75 | E44: =IF(B44="Daily",7, IF(B44="Weekly",1, IF(B44="Every Other Day",4,""))) -> 7 | F44: =+D44*E44 -> 525 | H44: 0 | I44: Case | J44: =H44*3.65 -> 0
E45: =SUM(E41:E44) -> 28 | F45: =SUM(F41:F44) -> 2100 | J45: =SUM(J39:J44) -> 547.12 | K45: =ROUNDUP(SUM(K39:K44),0) -> 795 | M45: Profit | N45: =+K45-J45 -> 247.88
E46: Number of Cartridges needed | F46: =+F45/300 -> 7 | I46: Per Unit | J46: =+J45/H39 -> 0.26053333 | K46: =+K45/H39 -> 0.37857143
K50: Reg Price
H51: =ROUNDUP(F57,0) -> 2100 | I51: Units | J51: =+B7*F57 -> 542.92 | K51: =+F57*G7 -> 787.92
A52: Month 3 | B52: Frequency of Injection | C52: mcg | D52: Units per Injections | E52: # of Injections | F52: Units Needed | H52: 0 | I52: Pen | J52: =+H52*45 -> 0 | K52: =+H52*85 -> 0
A53: Week 9 | B53: Daily | C53: 4000 | D53: 75 | E53: =IF(B53="Daily",7, IF(B53="Weekly",1, IF(B53="Every Other Day",4,""))) -> 7 | F53: =+D53*E53 -> 525 | H53: =IF(E57>=25, E57+2, E57+1) -> 30 | I53: Pen Needles
A54: Week 10 | B54: Daily | C54: 4000 | D54: 75 | E54: =IF(B54="Daily",7, IF(B54="Weekly",1, IF(B54="Every Other Day",4,""))) -> 7 | F54: =+D54*E54 -> 525 | H54: =ROUNDUP(F58,0) -> 7 | I54: Cartridges | J54: =H54*0.6 -> 4.2 | K54: =+H54 -> 7
A55: Week 11 | B55: Daily | C55: 4000 | D55: 75 | E55: =IF(B55="Daily",7, IF(B55="Weekly",1, IF(B55="Every Other Day",4,""))) -> 7 | F55: =+D55*E55 -> 525 | H55: =H53 -> 30 | I55: Alochol Prep
A56: Week 12 | B56: Daily | C56: 4000 | D56: 75 | E56: =IF(B56="Daily",7, IF(B56="Weekly",1, IF(B56="Every Other Day",4,""))) -> 7 | F56: =+D56*E56 -> 525 | H56: 0 | I56: Case | J56: =H56*3.65 -> 0
...

Sheet BPC157
A1: BPC-157 10mg | O1: Daily
B2: 48 | C2: cost | O2: Every Other Day
B3: 3.3 | C3: BAC | O3: Weekly
B4: 15 | C4: (30) Pen Needles, Cartridges, Alcohol Prep | F4: Add per vial | G4: Reg Price
B5: =SUM(B2:B4) -> 66.3 | F5: 100 | G5: =+F5+B5 -> 166.3
A7: Per Unit | B7: =+B5/300 -> 0.221 | F7: Per Unit | G7: =+G5/300 -> 0.55433333
A13: CUSTOM PROTOCOL | K13: Reg Price
H14: =ROUNDUP(F20,0) -> 285 | I14: Units | J14: =+B7*F20 -> 62.985 | K14: =+F20*G7 -> 157.985
B15: Frequency of Injection | C15: mcg | D15: Units per Injections | E15: # of Injections | F15: Units Needed | H15: 1 | I15: Pen | J15: =+H15*45 -> 45 | K15: =+H15*85 -> 85
A16: Week | B16: Daily | C16: 500 | D16: 15 | E16: =IF(B16="Daily",7, IF(B16="Weekly",1, IF(B16="Every Other Day",4,""))) -> 7 | F16: =+D16*E16 -> 105 | H16: =IF(E20>=25, E20+2, E20+1) -> 20 | I16: Pen Needles
A17: Week | B17: Every Other Day | C17: 500 | D17: 15 | E17: =IF(B17="Daily",7, IF(B17="Weekly",1, IF(B17="Every Other Day",4,""))) -> 4 | F17: =+D17*E17 -> 60 | H17: =ROUNDUP(F21,0) -> 1 | I17: Cartridges
A18: Week | B18: Daily | C18: 500 | D18: 15 | E18: =IF(B18="Daily",7, IF(B18="Weekly",1, IF(B18="Every Other Day",4,""))) -> 7 | F18: =+D18*E18 -> 105 | H18: =H16 -> 20 | I18: Alochol Prep
A19: Week | B19: Weekly | C19: 500 | D19: 15 | E19: =IF(B19="Daily",7, IF(B19="Weekly",1, IF(B19="Every Other Day",4,""))) -> 1 | F19: =+D19*E19 -> 15 | H19: 0 | I19: Case | J19: =H19*3.65 -> 0
E20: =SUM(E16:E19) -> 19 | F20: =SUM(F16:F19) -> 285 | J20: =SUM(J14:J19) -> 107.985 | K20: =ROUNDUP(SUM(K14:K19),0) -> 243 | M20: Profit | N20: =+K20-J20 -> 135.015
E21: Number of Cartridges needed | F21: =+F20/300 -> 0.95 | I21: Per Unit | J21: =+J20/H14 -> 0.37889474 | K21: =+K20/H14 -> 0.85263158
K26: Reg Price
H27: =ROUNDUP(F33,0) -> 252 | I27: Units | J27: =F33*B7 -> 55.692 | K27: =+F33*G7 -> 139.692
A28: Month 1 | B28: Frequency of Injection | C28: mcg | D28: Units per Injections | E28: # of Injections | F28: Units Needed | H28: 1 | I28: Pen | J28: =+H28*45 -> 45 | K28: =H28*85 -> 85
A29: Week 1 | B29: Daily | C29: 200 | D29: 6 | E29: =IF(B29="Daily",7, IF(B29="Weekly",1, IF(B29="Every Other Day",4,""))) -> 7 | F29: =+D29*E29 -> 42 | H29: =IF(E33>=25, E33+2, E33+1) -> 30 | I29: Pen Needles
A30: Week 2 | B30: Daily | C30: 200 | D30: 6 | E30: =IF(B30="Daily",7, IF(B30="Weekly",1, IF(B30="Every Other Day",4,""))) -> 7 | F30: =+D30*E30 -> 42 | H30: =ROUNDUP(F34,0) -> 1 | I30: Cartridges
A31: Week 3 | B31: Daily | C31: 400 | D31: 12 | E31: =IF(B31="Daily",7, IF(B31="Weekly",1, IF(B31="Every Other Day",4,""))) -> 7 | F31: =+D31*E31 -> 84 | H31: =H29 -> 30 | I31: Alochol Prep
A32: Week 4 | B32: Daily | C32: 400 | D32: 12 | E32: =IF(B32="Daily",7, IF(B32="Weekly",1, IF(B32="Every Other Day",4,""))) -> 7 | F32: =+D32*E32 -> 84 | H32: 1 | I32: Case | J32: =H32*3.65 -> 3.65
E33: =SUM(E29:E32) -> 28 | F33: =SUM(F29:F32) -> 252 | J33: =SUM(J27:J32) -> 104.342 | K33: =ROUNDUP(SUM(K27:K32),0) -> 225 | M33: Profit | N33: =+K33-J33 -> 120.658
E34: Number of Cartridges needed | F34: =+F33/300 -> 0.84 | I34: Per Unit | J34: =+J33/H27 -> 0.41405556 | K34: =+K33/H27 -> 0.89285714
K38: Reg Price
H39: =ROUNDUP(F45,0) -> 504 | I39: Units | J39: =+B7*F45 -> 111.384 | K39: =+F45*G7 -> 279.384
A40: Month 2 | B40: Frequency of Injection | C40: mcg | D40: Units per Injections | E40: # of Injections | F40: Units Needed | H40: 0 | I40: Pen | J40: =+H40*45 -> 0 | K40: =+H40*85 -> 0
A41: Week 5 | B41: Daily | C41: 600 | D41: 18 | E41: =IF(B41="Daily",7, IF(B41="Weekly",1, IF(B41="Every Other Day",4,""))) -> 7 | F41: =+D41*E41 -> 126 | H41: =IF(E45>=25, E45+2, E45+1) -> 30 | I41: Pen Needles
A42: Week 6 | B42: Daily | C42: 600 | D42: 18 | E42: =IF(B42="Daily",7, IF(B42="Weekly",1, IF(B42="Every Other Day",4,""))) -> 7 | F42: =+D42*E42 -> 126 | H42: =ROUNDUP(F46,0) -> 2 | I42: Cartridges
A43: Week 7 | B43: Daily | C43: 600 | D43: 18 | E43: =IF(B43="Daily",7, IF(B43="Weekly",1, IF(B43="Every Other Day",4,""))) -> 7 | F43: =+D43*E43 -> 126 | H43: =H41 -> 30 | I43: Alochol Prep
A44: Week 8 | B44: Daily | C44: 600 | D44: 18 | E44: =IF(B44="Daily",7, IF(B44="Weekly",1, IF(B44="Every Other Day",4,""))) -> 7 | F44: =+D44*E44 -> 126 | H44: 0 | I44: Case | J44: =H44*3.65 -> 0
E45: =SUM(E41:E44) -> 28 | F45: =SUM(F41:F44) -> 504 | J45: =SUM(J39:J44) -> 111.384 | K45: =ROUNDUP(SUM(K39:K44),0) -> 280 | M45: Profit | N45: =+K45-J45 -> 168.616
E46: Number of Cartridges needed | F46: =+F45/300 -> 1.68 | I46: Per Unit | J46: =+J45/H39 -> 0.221 | K46: =+K45/H39 -> 0.55555556
K50: Reg Price
H51: =ROUNDUP(F57,0) -> 504 | I51: Units | J51: =+F57*B7 -> 111.384 | K51: =+F57*G7 -> 279.384
A52: Month 3 | B52: Frequency of Injection | C52: mcg | D52: Units per Injections | E52: # of Injections | F52: Units Needed | H52: 0 | I52: Pen | J52: =+H52*45 -> 0 | K52: =+H52*85 -> 0
A53: Week 9 | B53: Daily | C53: 600 | D53: 18 | E53: =IF(B53="Daily",7, IF(B53="Weekly",1, IF(B53="Every Other Day",4,""))) -> 7 | F53: =+D53*E53 -> 126 | H53: =IF(E57>=25, E57+2, E57+1) -> 30 | I53: Pen Needles
A54: Week 10 | B54: Daily | C54: 600 | D54: 18 | E54: =IF(B54="Daily",7, IF(B54="Weekly",1, IF(B54="Every Other Day",4,""))) -> 7 | F54: =+D54*E54 -> 126 | H54: =ROUNDUP(F58,0) -> 2 | I54: Cartridges
A55: Week 11 | B55: Daily | C55: 600 | D55: 18 | E55: =IF(B55="Daily",7, IF(B55="Weekly",1, IF(B55="Every Other Day",4,""))) -> 7 | F55: =+D55*E55 -> 126 | H55: =H53 -> 30 | I55: Alochol Prep
A56: Week 12 | B56: Daily | C56: 600 | D56: 18 | E56: =IF(B56="Daily",7, IF(B56="Weekly",1, IF(B56="Every Other Day",4,""))) -> 7 | F56: =+D56*E56 -> 126 | H56: 0 | I56: Case | J56: =H56*3.65 -> 0
...

Sheet DSIP 5mg
A1: DSIP 5mg | N1: Daily
B2: ='Pep Costs'!B16 -> 37 | C2: cost | N2: Every Other Day
B3: 3.3 | C3: BAC | N3: Weekly
B4: 15 | C4: (30) Pen Needles, Cartridges, Alcohol Prep | E4: Add per vial | F4: Reg Price
B5: =SUM(B2:B4) -> 55.3 | E5: 100 | F5: =+E5+B5 -> 155.3
A7: Per Unit | B7: =+B5/300 -> 0.18433333 | E7: Per Unit | F7: =+F5/300 -> 0.51766667
A12: CUSTOM PROTOCOL
K14: Reg Price
H15: =ROUNDUP(F21,0) -> 285 | I15: Units | J15: =+B7*F21 -> 52.535 | K15: =+F21*F7 -> 147.535
B16: Frequency of Injection | C16: mcg | D16: Units per Injections | E16: # of Injections | F16: Units Needed | H16: 0 | I16: Pen | J16: =+H16*45 -> 0 | K16: =+H16*85 -> 0
A17: Week | B17: Daily | C17: 1000 | D17: 15 | E17: =IF(B17="Daily",7, IF(B17="Weekly",1, IF(B17="Every Other Day",4,""))) -> 7 | F17: =+D17*E17 -> 105 | H17: =IF(E21>=25, E21+2, E21+1) -> 20 | I17: Pen Needles
A18: Week | B18: Every Other Day | C18: 1000 | D18: 15 | E18: =IF(B18="Daily",7, IF(B18="Weekly",1, IF(B18="Every Other Day",4,""))) -> 4 | F18: =+D18*E18 -> 60 | H18: =ROUNDUP(F22,0) -> 1 | I18: Cartridges
A19: Week | B19: Weekly | C19: 1000 | D19: 15 | E19: =IF(B19="Daily",7, IF(B19="Weekly",1, IF(B19="Every Other Day",4,""))) -> 1 | F19: =+D19*E19 -> 15 | H19: =H17 -> 20 | I19: Alochol Prep
A20: Week | B20: Daily | C20: 1000 | D20: 15 | E20: =IF(B20="Daily",7, IF(B20="Weekly",1, IF(B20="Every Other Day",4,""))) -> 7 | F20: =+D20*E20 -> 105 | H20: 0 | I20: Case | J20: =H20*3.65 -> 0
E21: =SUM(E17:E20) -> 19 | F21: =SUM(F17:F20) -> 285 | J21: =SUM(J15:J20) -> 52.535 | K21: =ROUNDUP(SUM(K15:K20),0) -> 148 | M21: Profit | N21: =+K21-J21 -> 95.465
E22: Number of Cartridges needed | F22: =+F21/300 -> 0.95 | I22: Per Unit | J22: =+J21/H15 -> 0.18433333 | K22: =+K21/H15 -> 0.51929825
K28: Reg Price
H29: =ROUNDUP(F35,0) -> 294 | I29: Units | J29: =F35*B7 -> 54.194 | K29: =+F35*F7 -> 152.194
A30: Month 1 | B30: Frequency of Injection | C30: mcg | D30: Units per Injections | E30: # of Injections | F30: Units Needed | H30: 0 | I30: Pen | J30: =+H30*45 -> 0 | K30: =H30*85 -> 0
A31: Week 1 | B31: Daily | C31: 100 | D31: 6 | E31: =IF(B31="Daily",7, IF(B31="Weekly",1, IF(B31="Every Other Day",4,""))) -> 7 | F31: =+D31*E31 -> 42 | H31: =IF(E35>=25, E35+2, E35+1) -> 30 | I31: Pen Needles
A32: Week 2 | B32: Daily | C32: 150 | D32: 9 | E32: =IF(B32="Daily",7, IF(B32="Weekly",1, IF(B32="Every Other Day",4,""))) -> 7 | F32: =+D32*E32 -> 63 | H32: =ROUNDUP(F36,0) -> 1 | I32: Cartridges
A33: Week 3 | B33: Daily | C33: 200 | D33: 12 | E33: =IF(B33="Daily",7, IF(B33="Weekly",1, IF(B33="Every Other Day",4,""))) -> 7 | F33: =+D33*E33 -> 84 | H33: =H31 -> 30 | I33: Alochol Prep
A34: Week 4 | B34: Daily | C34: 250 | D34: 15 | E34: =IF(B34="Daily",7, IF(B34="Weekly",1, IF(B34="Every Other Day",4,""))) -> 7 | F34: =+D34*E34 -> 105 | H34: 1 | I34: Case | J34: =H34*3.65 -> 3.65
E35: =SUM(E31:E34) -> 28 | F35: =SUM(F31:F34) -> 294 | J35: =SUM(J29:J34) -> 57.844 | K35: =ROUNDUP(SUM(K29:K34),0) -> 153 | M35: Profit | N35: =+K35-J35 -> 95.156
E36: Number of Cartridges needed | F36: =+F35/300 -> 0.98 | I36: Per Unit | J36: =+J35/H29 -> 0.1967483 | K36: =+K35/H29 -> 0.52040816
K40: Reg Price
H41: =ROUNDUP(F47,0) -> 483 | I41: Units | J41: =+B7*F47 -> 89.033 | K41: =+F47*F7 -> 250.033
A42: Month 2 | B42: Frequency of Injection | C42: mcg | D42: Units per Injections | E42: # of Injections | F42: Units Needed | H42: 0 | I42: Pen | J42: =+H42*45 -> 0 | K42: =+H42*85 -> 0
A43: Week 5 | B43: Daily | C43: 250 | D43: 15 | E43: =IF(B43="Daily",7, IF(B43="Weekly",1, IF(B43="Every Other Day",4,""))) -> 7 | F43: =+D43*E43 -> 105 | H43: =IF(E47>=25, E47+2, E47+1) -> 30 | I43: Pen Needles
A44: Week 6 | B44: Daily | C44: 300 | D44: 18 | E44: =IF(B44="Daily",7, IF(B44="Weekly",1, IF(B44="Every Other Day",4,""))) -> 7 | F44: =+D44*E44 -> 126 | H44: =ROUNDUP(F48,0) -> 2 | I44: Cartridges
A45: Week 7 | B45: Daily | C45: 300 | D45: 18 | E45: =IF(B45="Daily",7, IF(B45="Weekly",1, IF(B45="Every Other Day",4,""))) -> 7 | F45: =+D45*E45 -> 126 | H45: =H43 -> 30 | I45: Alochol Prep
A46: Week 8 | B46: Daily | C46: 300 | D46: 18 | E46: =IF(B46="Daily",7, IF(B46="Weekly",1, IF(B46="Every Other Day",4,""))) -> 7 | F46: =+D46*E46 -> 126 | H46: 0 | I46: Case | J46: =H46*3.65 -> 0
E47: =SUM(E43:E46) -> 28 | F47: =SUM(F43:F46) -> 483 | J47: =SUM(J41:J46) -> 89.033 | K47: =ROUNDUP(SUM(K41:K46),0) -> 251
E48: Number of Cartridges needed | F48: =+F47/300 -> 1.61 | I48: Per Unit | J48: =+J47/H41 -> 0.18433333 | K48: =+K47/H41 -> 0.51966874 | M48: Profit | N48: =+K47-J47 -> 161.967
A52: Weeks 9-12: see below OR…..
B53: The patient needs to have a conversation with Unruh as they will most likely take this month OFF.
B54: When the patient returns they may continue to match Week 9-12 or go on a custome protocol
K58: Reg Price
H59: =ROUNDUP(F65,0) -> 546 | I59: Units | J59: =+B7*F65 -> 100.646 | K59: =+F65*F7 -> 282.646
A60: Month 3 | B60: Frequency of Injection | C60: mcg | D60: Units per Injections | E60: # of Injections | F60: Units Needed | H60: 0 | I60: Pen | J60: =+H60*45 -> 0 | K60: =+H60*85 -> 0
...

Sheet DSIP 10mg
A1: DSIP 10mg | N1: Daily
B2: ='Pep Costs'!B17 -> 47 | C2: cost | N2: Every Other Day
B3: 3.3 | C3: BAC | N3: Weekly
B4: 15 | C4: (30) Pen Needles, Cartridges, Alcohol Prep | F4: Add per vial | G4: Reg Price
B5: =SUM(B2:B4) -> 65.3 | F5: 100 | G5: =+F5+B5 -> 165.3
A7: Per Unit | B7: =+B5/300 -> 0.21766667 | F7: Per Unit | G7: =+G5/300 -> 0.551
A13: CUSTOM PROTOCOL | K13: Reg Price
H14: =ROUNDUP(F20,0) -> 57 | I14: Units | J14: =+B7*F20 -> 12.407 | K14: =+F20*G7 -> 31.407
B15: Frequency of Injection | C15: mcg | D15: Units per Injections | E15: # of Injections | F15: Units Needed | H15: 0 | I15: Pen | J15: =+H15*45 -> 0 | K15: =+H15*85 -> 0
A16: Week | B16: Every Other Day | C16: 100 | D16: 3 | E16: =IF(B16="Daily",7, IF(B16="Weekly",1, IF(B16="Every Other Day",4,""))) -> 4 | F16: =+D16*E16 -> 12 | H16: =IF(E20>=25, E20+2, E20+1) -> 20 | I16: Pen Needles
A17: Week | B17: Daily | C17: 100 | D17: 3 | E17: =IF(B17="Daily",7, IF(B17="Weekly",1, IF(B17="Every Other Day",4,""))) -> 7 | F17: =+D17*E17 -> 21 | H17: =ROUNDUP(F21,0) -> 1 | I17: Cartridges
A18: Week | B18: Weekly | C18: 100 | D18: 3 | E18: =IF(B18="Daily",7, IF(B18="Weekly",1, IF(B18="Every Other Day",4,""))) -> 1 | F18: =+D18*E18 -> 3 | H18: =H16 -> 20 | I18: Alochol Prep
A19: Week | B19: Daily | C19: 10 | D19: 3 | E19: =IF(B19="Daily",7, IF(B19="Weekly",1, IF(B19="Every Other Day",4,""))) -> 7 | F19: =+D19*E19 -> 21 | H19: 0 | I19: Case | J19: =H19*3.65 -> 0
E20: =SUM(E16:E19) -> 19 | F20: =SUM(F16:F19) -> 57 | J20: =SUM(J14:J19) -> 12.407 | K20: =ROUNDUP(SUM(K14:K19),0) -> 32 | M20: Profit | N20: =+K20-J20 -> 19.593
E21: Number of Cartridges needed | F21: =+F20/300 -> 0.19 | I21: Per Unit | J21: =+J20/H14 -> 0.21766667 | K21: =+K20/H14 -> 0.56140351
K27: Reg Price
H28: =ROUNDUP(F34,0) -> 154 | I28: Units | J28: =F34*B7 -> 33.520667 | K28: =+F34*G7 -> 84.854
A29: Month 1 | B29: Frequency of Injection | C29: mcg | D29: Units per Injections | E29: # of Injections | F29: Units Needed | H29: 0 | I29: Pen | J29: =+H29*45 -> 0 | K29: =H29*85 -> 0
A30: Week 1 | B30: Daily | C30: 100 | D30: 3 | E30: =IF(B30="Daily",7, IF(B30="Weekly",1, IF(B30="Every Other Day",4,""))) -> 7 | F30: =+D30*E30 -> 21 | H30: =IF(E34>=25, E34+2, E34+1) -> 30 | I30: Pen Needles
A31: Week 2 | B31: Daily | C31: 150 | D31: 5 | E31: =IF(B31="Daily",7, IF(B31="Weekly",1, IF(B31="Every Other Day",4,""))) -> 7 | F31: =+D31*E31 -> 35 | H31: =ROUNDUP(F35,0) -> 1 | I31: Cartridges
A32: Week 3 | B32: Daily | C32: 200 | D32: 6 | E32: =IF(B32="Daily",7, IF(B32="Weekly",1, IF(B32="Every Other Day",4,""))) -> 7 | F32: =+D32*E32 -> 42 | H32: =H30 -> 30 | I32: Alochol Prep
A33: Week 4 | B33: Daily | C33: 250 | D33: 8 | E33: =IF(B33="Daily",7, IF(B33="Weekly",1, IF(B33="Every Other Day",4,""))) -> 7 | F33: =+D33*E33 -> 56 | H33: 1 | I33: Case | J33: =H33*3.65 -> 3.65
E34: =SUM(E30:E33) -> 28 | F34: =SUM(F30:F33) -> 154 | J34: =SUM(J28:J33) -> 37.170667 | K34: =ROUNDUP(SUM(K28:K33),0) -> 85 | M34: Profit | N34: =+K34-J34 -> 47.829333
